Workbook

Sheet Результаты
A1: x | B1: Решение уравнения, y(x)
B2: Метод 1 | D2: Метод 5
B3: h = 0,01 | C3: h = 0,001 | D3: h = 0,01 | E3: h = 0,001
A4: 0 | B4: 1 | C4: ='Метод 1 (h = 0,001)'!B2 -> 1 | D4: ='Метод 5 (h = 0,01)'!B2 -> 1 | E4: ='Метод 5 (h = 0,001)'!B2 -> 1
A5: 0.01 | B5: =B4+0.01*(A4*EXP(-A4^2)-2*A4*B4) -> 1 | C5: ='Метод 1 (h = 0,001)'!B12 -> 0.999955 | D5: ='Метод 5 (h = 0,01)'!B3 -> 0.99995 | E5: ='Метод 5 (h = 0,001)'!B12 -> 0.99995
A6: 0.02 | B6: =B5+0.01*(A5*EXP(-A5^2)-2*A5*B5) -> 0.99990001 | C6: ='Метод 1 (h = 0,001)'!B22 -> 0.99981007 | D6: ='Метод 5 (h = 0,01)'!B4 -> 0.99980008 | E6: ='Метод 5 (h = 0,001)'!B22 -> 0.99980008
A7: 0.03 | B7: =B6+0.01*(A6*EXP(-A6^2)-2*A6*B6) -> 0.99970013 | C7: ='Метод 1 (h = 0,001)'!B32 -> 0.99956537 | D7: ='Метод 5 (h = 0,01)'!B5 -> 0.9995504 | E7: ='Метод 5 (h = 0,001)'!B32 -> 0.9995504
A8: 0.04 | B8: =B7+0.01*(A7*EXP(-A7^2)-2*A7*B7) -> 0.99940058 | C8: ='Метод 1 (h = 0,001)'!B42 -> 0.9992212 | D8: ='Метод 5 (h = 0,01)'!B6 -> 0.99920128 | E8: ='Метод 5 (h = 0,001)'!B42 -> 0.99920128
A9: 0.05 | B9: =B8+0.01*(A8*EXP(-A8^2)-2*A8*B8) -> 0.9990017 | C9: ='Метод 1 (h = 0,001)'!B52 -> 0.99877796 | D9: ='Метод 5 (h = 0,01)'!B7 -> 0.99875312 | E9: ='Метод 5 (h = 0,001)'!B52 -> 0.99875312
A10: 0.06 | B10: =B9+0.01*(A9*EXP(-A9^2)-2*A9*B9) -> 0.99850395 | C10: ='Метод 1 (h = 0,001)'!B62 -> 0.99823619 | D10: ='Метод 5 (h = 0,01)'!B8 -> 0.99820648 | E10: ='Метод 5 (h = 0,001)'!B62 -> 0.99820648
A11: 0.07 | B11: =B10+0.01*(A10*EXP(-A10^2)-2*A10*B10) -> 0.99790791 | C11: ='Метод 1 (h = 0,001)'!B72 -> 0.99759654 | D11: ='Метод 5 (h = 0,01)'!B9 -> 0.997562 | E11: ='Метод 5 (h = 0,001)'!B72 -> 0.997562
A12: 0.08 | B12: =B11+0.01*(A11*EXP(-A11^2)-2*A11*B11) -> 0.99721428 | C12: ='Метод 1 (h = 0,001)'!B82 -> 0.99685978 | D12: ='Метод 5 (h = 0,01)'!B10 -> 0.99682046 | E12: ='Метод 5 (h = 0,001)'!B82 -> 0.99682046
A13: 0.09 | B13: =B12+0.01*(A12*EXP(-A12^2)-2*A12*B12) -> 0.99642387 | C13: ='Метод 1 (h = 0,001)'!B92 -> 0.9960268 | D13: ='Метод 5 (h = 0,01)'!B11 -> 0.99598276 | E13: ='Метод 5 (h = 0,001)'!B92 -> 0.99598276
A14: 0.1 | B14: =B13+0.01*(A13*EXP(-A13^2)-2*A13*B13) -> 0.99553763 | C14: ='Метод 1 (h = 0,001)'!B102 -> 0.9950986 | D14: ='Метод 5 (h = 0,01)'!B12 -> 0.99504992 | E14: ='Метод 5 (h = 0,001)'!B102 -> 0.99504992
A15: 0.11 | B15: =B14+0.01*(A14*EXP(-A14^2)-2*A14*B14) -> 0.9945566 | C15: ='Метод 1 (h = 0,001)'!B112 -> 0.99407631 | D15: ='Метод 5 (h = 0,01)'!B13 -> 0.99402306 | E15: ='Метод 5 (h = 0,001)'!B112 -> 0.99402306
A16: 0.12 | B16: =B15+0.01*(A15*EXP(-A15^2)-2*A15*B15) -> 0.99348197 | C16: ='Метод 1 (h = 0,001)'!B122 -> 0.99296116 | D16: ='Метод 5 (h = 0,01)'!B14 -> 0.99290343 | E16: ='Метод 5 (h = 0,001)'!B122 -> 0.99290343
A17: 0.13 | B17: =B16+0.01*(A16*EXP(-A16^2)-2*A16*B16) -> 0.99231502 | C17: ='Метод 1 (h = 0,001)'!B132 -> 0.99175452 | D17: ='Метод 5 (h = 0,01)'!B15 -> 0.99169241 | E17: ='Метод 5 (h = 0,001)'!B132 -> 0.99169241
A18: 0.14 | B18: =B17+0.01*(A17*EXP(-A17^2)-2*A17*B17) -> 0.99105715 | C18: ='Метод 1 (h = 0,001)'!B142 -> 0.99045786 | D18: ='Метод 5 (h = 0,01)'!B16 -> 0.99039146 | E18: ='Метод 5 (h = 0,001)'!B142 -> 0.99039146
A19: 0.15 | B19: =B18+0.01*(A18*EXP(-A18^2)-2*A18*B18) -> 0.9897099 | C19: ='Метод 1 (h = 0,001)'!B152 -> 0.98907277 | D19: ='Метод 5 (h = 0,01)'!B17 -> 0.98900219 | E19: ='Метод 5 (h = 0,001)'!B152 -> 0.98900219
A20: 0.16 | B20: =B19+0.01*(A19*EXP(-A19^2)-2*A19*B19) -> 0.98827491 | C20: ='Метод 1 (h = 0,001)'!B162 -> 0.98760094 | D20: ='Метод 5 (h = 0,01)'!B18 -> 0.9875263 | E20: ='Метод 5 (h = 0,001)'!B162 -> 0.9875263
A21: 0.17 | B21: =B20+0.01*(A20*EXP(-A20^2)-2*A20*B20) -> 0.98675392 | C21: ='Метод 1 (h = 0,001)'!B172 -> 0.98604421 | D21: ='Метод 5 (h = 0,01)'!B19 -> 0.98596562 | E21: ='Метод 5 (h = 0,001)'!B172 -> 0.98596562
A22: 0.18 | B22: =B21+0.01*(A21*EXP(-A21^2)-2*A21*B21) -> 0.9851488 | C22: ='Метод 1 (h = 0,001)'!B182 -> 0.98440449 | D22: ='Метод 5 (h = 0,01)'!B20 -> 0.98432209 | E22: ='Метод 5 (h = 0,001)'!B182 -> 0.98432209
A23: 0.19 | B23: =B22+0.01*(A22*EXP(-A22^2)-2*A22*B22) -> 0.98346154 | C23: ='Метод 1 (h = 0,001)'!B192 -> 0.98268383 | D23: ='Метод 5 (h = 0,01)'!B21 -> 0.98259776 | E23: ='Метод 5 (h = 0,001)'!B192 -> 0.98259776
A24: 0.2 | B24: =B23+0.01*(A23*EXP(-A23^2)-2*A23*B23) -> 0.98169423 | C24: ='Метод 1 (h = 0,001)'!B202 -> 0.98088439 | D24: ='Метод 5 (h = 0,01)'!B22 -> 0.98079477 | E24: ='Метод 5 (h = 0,001)'!B202 -> 0.98079477
A25: 0.21 | B25: =B24+0.01*(A24*EXP(-A24^2)-2*A24*B24) -> 0.97984907 | C25: ='Метод 1 (h = 0,001)'!B212 -> 0.97900842 | D25: ='Метод 5 (h = 0,01)'!B23 -> 0.97891541 | E25: ='Метод 5 (h = 0,001)'!B212 -> 0.97891541
A26: 0.22 | B26: =B25+0.01*(A25*EXP(-A25^2)-2*A25*B25) -> 0.97792839 | C26: ='Метод 1 (h = 0,001)'!B222 -> 0.9770583 | D26: ='Метод 5 (h = 0,01)'!B24 -> 0.97696206 | E26: ='Метод 5 (h = 0,001)'!B222 -> 0.97696206
A27: 0.23 | B27: =B26+0.01*(A26*EXP(-A26^2)-2*A26*B26) -> 0.9759346 | C27: ='Метод 1 (h = 0,001)'!B232 -> 0.97503651 | D27: ='Метод 5 (h = 0,01)'!B25 -> 0.97493719 | E27: ='Метод 5 (h = 0,001)'!B232 -> 0.97493719
A28: 0.24 | B28: =B27+0.01*(A27*EXP(-A27^2)-2*A27*B27) -> 0.97387025 | C28: ='Метод 1 (h = 0,001)'!B242 -> 0.97294564 | D28: ='Метод 5 (h = 0,01)'!B26 -> 0.97284341 | E28: ='Метод 5 (h = 0,001)'!B242 -> 0.97284341
A29: 0.25 | B29: =B28+0.01*(A28*EXP(-A28^2)-2*A28*B28) -> 0.97173797 | C29: ='Метод 1 (h = 0,001)'!B252 -> 0.97078837 | D29: ='Метод 5 (h = 0,01)'!B27 -> 0.97068341 | E29: ='Метод 5 (h = 0,001)'!B252 -> 0.97068341
A30: 0.26 | B30: =B29+0.01*(A29*EXP(-A29^2)-2*A29*B29) -> 0.96954052 | C30: ='Метод 1 (h = 0,001)'!B262 -> 0.96856753 | D30: ='Метод 5 (h = 0,01)'!B28 -> 0.96846 | E30: ='Метод 5 (h = 0,001)'!B262 -> 0.96846
A31: 0.27 | B31: =B30+0.01*(A30*EXP(-A30^2)-2*A30*B30) -> 0.96728074 | C31: ='Метод 1 (h = 0,001)'!B272 -> 0.96628599 | D31: ='Метод 5 (h = 0,01)'!B29 -> 0.96617609 | E31: ='Метод 5 (h = 0,001)'!B272 -> 0.96617609
A32: 0.28 | B32: =B31+0.01*(A31*EXP(-A31^2)-2*A31*B31) -> 0.96496161 | C32: ='Метод 1 (h = 0,001)'!B282 -> 0.96394678 | D32: ='Метод 5 (h = 0,01)'!B30 -> 0.96383468 | E32: ='Метод 5 (h = 0,001)'!B282 -> 0.96383468
A33: 0.29 | B33: =B32+0.01*(A32*EXP(-A32^2)-2*A32*B32) -> 0.96258618 | C33: ='Метод 1 (h = 0,001)'!B292 -> 0.961553 | D33: ='Метод 5 (h = 0,01)'!B31 -> 0.9614389 | E33: ='Метод 5 (h = 0,001)'!B292 -> 0.9614389
A34: 0.3 | B34: =B33+0.01*(A33*EXP(-A33^2)-2*A33*B33) -> 0.96015762 | C34: ='Метод 1 (h = 0,001)'!B302 -> 0.95910785 | D34: ='Метод 5 (h = 0,01)'!B32 -> 0.95899196 | E34: ='Метод 5 (h = 0,001)'!B302 -> 0.95899196
A35: 0.31 | B35: =B34+0.01*(A34*EXP(-A34^2)-2*A34*B34) -> 0.9576792 | C35: ='Метод 1 (h = 0,001)'!B312 -> 0.95661466 | D35: ='Метод 5 (h = 0,01)'!B33 -> 0.95649717 | E35: ='Метод 5 (h = 0,001)'!B312 -> 0.95649717
A36: 0.32 | B36: =B35+0.01*(A35*EXP(-A35^2)-2*A35*B35) -> 0.95515428 | C36: ='Метод 1 (h = 0,001)'!B322 -> 0.95407683 | D36: ='Метод 5 (h = 0,01)'!B34 -> 0.95395794 | E36: ='Метод 5 (h = 0,001)'!B322 -> 0.95395794
A37: 0.33 | B37: =B36+0.01*(A36*EXP(-A36^2)-2*A36*B36) -> 0.95258634 | C37: ='Метод 1 (h = 0,001)'!B332 -> 0.95149786 | D37: ='Метод 5 (h = 0,01)'!B35 -> 0.95137778 | E37: ='Метод 5 (h = 0,001)'!B332 -> 0.95137778
A38: 0.34 | B38: =B37+0.01*(A37*EXP(-A37^2)-2*A37*B37) -> 0.94997893 | C38: ='Метод 1 (h = 0,001)'!B342 -> 0.94888135 | D38: ='Метод 5 (h = 0,01)'!B36 -> 0.9487603 | E38: ='Метод 5 (h = 0,001)'!B342 -> 0.9487603
A39: 0.35 | B39: =B38+0.01*(A38*EXP(-A38^2)-2*A38*B38) -> 0.94733574 | C39: ='Метод 1 (h = 0,001)'!B352 -> 0.94623101 | D39: ='Метод 5 (h = 0,01)'!B37 -> 0.94610921 | E39: ='Метод 5 (h = 0,001)'!B352 -> 0.94610921
A40: 0.36 | B40: =B39+0.01*(A39*EXP(-A39^2)-2*A39*B39) -> 0.9446605 | C40: ='Метод 1 (h = 0,001)'!B362 -> 0.94355062 | D40: ='Метод 5 (h = 0,01)'!B38 -> 0.94342829 | E40: ='Метод 5 (h = 0,001)'!B362 -> 0.94342829
...

Sheet Метод 1 (h = 0,001)
A1: x | B1: y | C1: f(x,y)
A2: 0 | B2: 1 | C2: =A2*EXP(-A2^2)-2*A2*B2 -> 0
A3: =A2+0.001 -> 0.001 | B3: =B2+0.001*C2 -> 1 | C3: =A3*EXP(-A3^2)-2*A3*B3 -> -0.000999999
A4: =A3+0.001 -> 0.002 | B4: =B3+0.001*C3 -> 0.999999 | C4: =A4*EXP(-A4^2)-2*A4*B4 -> -0.001999988
A5: =A4+0.001 -> 0.003 | B5: =B4+0.001*C4 -> 0.999997 | C5: =A5*EXP(-A5^2)-2*A5*B5 -> -0.002999955
A6: =A5+0.001 -> 0.004 | B6: =B5+0.001*C5 -> 0.999994 | C6: =A6*EXP(-A6^2)-2*A6*B6 -> -0.003999888
A7: =A6+0.001 -> 0.005 | B7: =B6+0.001*C6 -> 0.99999 | C7: =A7*EXP(-A7^2)-2*A7*B7 -> -0.004999775
A8: =A7+0.001 -> 0.006 | B8: =B7+0.001*C7 -> 0.999985 | C8: =A8*EXP(-A8^2)-2*A8*B8 -> -0.005999604
A9: =A8+0.001 -> 0.007 | B9: =B8+0.001*C8 -> 0.999979 | C9: =A9*EXP(-A9^2)-2*A9*B9 -> -0.006999363
A10: =A9+0.001 -> 0.008 | B10: =B9+0.001*C9 -> 0.999972 | C10: =A10*EXP(-A10^2)-2*A10*B10 -> -0.00799904
A11: =A10+0.001 -> 0.009 | B11: =B10+0.001*C10 -> 0.999964 | C11: =A11*EXP(-A11^2)-2*A11*B11 -> -0.008998623
A12: =A11+0.001 -> 0.01 | B12: =B11+0.001*C11 -> 0.999955 | C12: =A12*EXP(-A12^2)-2*A12*B12 -> -0.0099981
A13: =A12+0.001 -> 0.011 | B13: =B12+0.001*C12 -> 0.99994501 | C13: =A13*EXP(-A13^2)-2*A13*B13 -> -0.010997459
A14: =A13+0.001 -> 0.012 | B14: =B13+0.001*C13 -> 0.99993401 | C14: =A14*EXP(-A14^2)-2*A14*B14 -> -0.011996688
... A1002: =A1001+0.001 -> 1 | B1002: =B1001+0.001*C1001 -> 0.9551235 | C1002: =A1002*EXP(-A1002^2)-2*A1002*B1002 -> 0.80803483

Sheet Метод 5 (h = 0,01)
A1: x | B1: y | C1: k1 | D1: k2 | E1: k3 | F1: k4 | G1: y_new
A2: 0 | B2: 1 | C2: =0.01*(A2*EXP(-A2^2)-2*A2*B2) -> 0 | D2: =0.01*((A2+0.005)*EXP(-(A2+0.005)^2)-2*(A2+0.005)*(B2+C2/2)) -> -4.999875e-05 | E2: =0.01*((A2+0.005)*EXP(-(A2+0.005)^2)-2*(A2+0.005)*(B2+D2/2)) -> -4.999625e-05 | F2: =0.01*((A2+0.01)*EXP(-(A2+0.01)^2)-2*(A2+0.01)*(B2+E2)) -> -9.998e-05 | G2: =B2+(C2+2*D2+2*E2+F2)/6 -> 0.99995
A3: =A2+0.01 -> 0.01 | B3: =G2 -> 0.99995 | C3: =0.01*(A3*EXP(-A3^2)-2*A3*B3) -> -9.998e-05 | D3: =0.01*((A3+0.005)*EXP(-(A3+0.005)^2)-2*(A3+0.005)*(B3+C3/2)) -> -0.00014993625 | E3: =0.01*((A3+0.005)*EXP(-(A3+0.005)^2)-2*(A3+0.005)*(B3+D3/2)) -> -0.00014992876 | F3: =0.01*((A3+0.01)*EXP(-(A3+0.01)^2)-2*(A3+0.01)*(B3+E3)) -> -0.00019984001 | G3: =B3+(C3+2*D3+2*E3+F3)/6 -> 0.99980008
A4: =A3+0.01 -> 0.02 | B4: =G3 -> 0.99980008 | C4: =0.01*(A4*EXP(-A4^2)-2*A4*B4) -> -0.00019984002 | D4: =0.01*((A4+0.005)*EXP(-(A4+0.005)^2)-2*(A4+0.005)*(B4+C4/2)) -> -0.00024969378 | E4: =0.01*((A4+0.005)*EXP(-(A4+0.005)^2)-2*(A4+0.005)*(B4+D4/2)) -> -0.00024968132 | F4: =0.01*((A4+0.01)*EXP(-(A4+0.01)^2)-2*(A4+0.01)*(B4+E4)) -> -0.00029946012 | G4: =B4+(C4+2*D4+2*E4+F4)/6 -> 0.9995504
A5: =A4+0.01 -> 0.03 | B5: =G4 -> 0.9995504 | C5: =0.01*(A5*EXP(-A5^2)-2*A5*B5) -> -0.00029946012 | D5: =0.01*((A5+0.005)*EXP(-(A5+0.005)^2)-2*(A5+0.005)*(B5+C5/2)) -> -0.00034915146 | E5: =0.01*((A5+0.005)*EXP(-(A5+0.005)^2)-2*(A5+0.005)*(B5+D5/2)) -> -0.00034913407 | F5: =0.01*((A5+0.01)*EXP(-(A5+0.01)^2)-2*(A5+0.01)*(B5+E5)) -> -0.0003987205 | G5: =B5+(C5+2*D5+2*E5+F5)/6 -> 0.99920128
A6: =A5+0.01 -> 0.04 | B6: =G5 -> 0.99920128 | C6: =0.01*(A6*EXP(-A6^2)-2*A6*B6) -> -0.00039872051 | D6: =0.01*((A6+0.005)*EXP(-(A6+0.005)^2)-2*(A6+0.005)*(B6+C6/2)) -> -0.00044818955 | E6: =0.01*((A6+0.005)*EXP(-(A6+0.005)^2)-2*(A6+0.005)*(B6+D6/2)) -> -0.00044816729 | F6: =0.01*((A6+0.01)*EXP(-(A6+0.01)^2)-2*(A6+0.01)*(B6+E6)) -> -0.00049750155 | G6: =B6+(C6+2*D6+2*E6+F6)/6 -> 0.99875312
A7: =A6+0.01 -> 0.05 | B7: =G6 -> 0.99875312 | C7: =0.01*(A7*EXP(-A7^2)-2*A7*B7) -> -0.00049750156 | D7: =0.01*((A7+0.005)*EXP(-(A7+0.005)^2)-2*(A7+0.005)*(B7+C7/2)) -> -0.00054668854 | E7: =0.01*((A7+0.005)*EXP(-(A7+0.005)^2)-2*(A7+0.005)*(B7+D7/2)) -> -0.00054666149 | F7: =0.01*((A7+0.01)*EXP(-(A7+0.01)^2)-2*(A7+0.01)*(B7+E7)) -> -0.00059568386 | G7: =B7+(C7+2*D7+2*E7+F7)/6 -> 0.99820648
A8: =A7+0.01 -> 0.06 | B8: =G7 -> 0.99820648 | C8: =0.01*(A8*EXP(-A8^2)-2*A8*B8) -> -0.00059568388 | D8: =0.01*((A8+0.005)*EXP(-(A8+0.005)^2)-2*(A8+0.005)*(B8+C8/2)) -> -0.00064452916 | E8: =0.01*((A8+0.005)*EXP(-(A8+0.005)^2)-2*(A8+0.005)*(B8+D8/2)) -> -0.00064449742 | F8: =0.01*((A8+0.01)*EXP(-(A8+0.01)^2)-2*(A8+0.01)*(B8+E8)) -> -0.00069314835 | G8: =B8+(C8+2*D8+2*E8+F8)/6 -> 0.997562
A9: =A8+0.01 -> 0.07 | B9: =G8 -> 0.997562 | C9: =0.01*(A9*EXP(-A9^2)-2*A9*B9) -> -0.00069314838 | D9: =0.01*((A9+0.005)*EXP(-(A9+0.005)^2)-2*(A9+0.005)*(B9+C9/2)) -> -0.00074159249 | E9: =0.01*((A9+0.005)*EXP(-(A9+0.005)^2)-2*(A9+0.005)*(B9+D9/2)) -> -0.00074155616 | F9: =0.01*((A9+0.01)*EXP(-(A9+0.01)^2)-2*(A9+0.01)*(B9+E9)) -> -0.00078977628 | G9: =B9+(C9+2*D9+2*E9+F9)/6 -> 0.99682046
A10: =A9+0.01 -> 0.08 | B10: =G9 -> 0.99682046 | C10: =0.01*(A10*EXP(-A10^2)-2*A10*B10) -> -0.00078977631 | D10: =0.01*((A10+0.005)*EXP(-(A10+0.005)^2)-2*(A10+0.005)*(B10+C10/2)) -> -0.00083775998 | E10: =0.01*((A10+0.005)*EXP(-(A10+0.005)^2)-2*(A10+0.005)*(B10+D10/2)) -> -0.00083771919 | F10: =0.01*((A10+0.01)*EXP(-(A10+0.01)^2)-2*(A10+0.01)*(B10+E10)) -> -0.00088544933 | G10: =B10+(C10+2*D10+2*E10+F10)/6 -> 0.99598276
A11: =A10+0.01 -> 0.09 | B11: =G10 -> 0.99598276 | C11: =0.01*(A11*EXP(-A11^2)-2*A11*B11) -> -0.00088544937 | D11: =0.01*((A11+0.005)*EXP(-(A11+0.005)^2)-2*(A11+0.005)*(B11+C11/2)) -> -0.00093291351 | E11: =0.01*((A11+0.005)*EXP(-(A11+0.005)^2)-2*(A11+0.005)*(B11+D11/2)) -> -0.00093286842 | F11: =0.01*((A11+0.01)*EXP(-(A11+0.01)^2)-2*(A11+0.01)*(B11+E11)) -> -0.00098004962 | G11: =B11+(C11+2*D11+2*E11+F11)/6 -> 0.99504992
A12: =A11+0.01 -> 0.1 | B12: =G11 -> 0.99504992 | C12: =0.01*(A12*EXP(-A12^2)-2*A12*B12) -> -0.00098004967 | D12: =0.01*((A12+0.005)*EXP(-(A12+0.005)^2)-2*(A12+0.005)*(B12+C12/2)) -> -0.0010269355 | E12: =0.01*((A12+0.005)*EXP(-(A12+0.005)^2)-2*(A12+0.005)*(B12+D12/2)) -> -0.0010268862 | F12: =0.01*((A12+0.01)*EXP(-(A12+0.01)^2)-2*(A12+0.01)*(B12+E12)) -> -0.0010734598 | G12: =B12+(C12+2*D12+2*E12+F12)/6 -> 0.99402306
A13: =A12+0.01 -> 0.11 | B13: =G12 -> 0.99402306 | C13: =0.01*(A13*EXP(-A13^2)-2*A13*B13) -> -0.0010734599 | D13: =0.01*((A13+0.005)*EXP(-(A13+0.005)^2)-2*(A13+0.005)*(B13+C13/2)) -> -0.0011197088 | E13: =0.01*((A13+0.005)*EXP(-(A13+0.005)^2)-2*(A13+0.005)*(B13+D13/2)) -> -0.0011196556 | F13: =0.01*((A13+0.01)*EXP(-(A13+0.01)^2)-2*(A13+0.01)*(B13+E13)) -> -0.0011655632 | G13: =B13+(C13+2*D13+2*E13+F13)/6 -> 0.99290343
A14: =A13+0.01 -> 0.12 | B14: =G13 -> 0.99290343 | C14: =0.01*(A14*EXP(-A14^2)-2*A14*B14) -> -0.0011655632 | D14: =0.01*((A14+0.005)*EXP(-(A14+0.005)^2)-2*(A14+0.005)*(B14+C14/2)) -> -0.001211117 | E14: =0.01*((A14+0.005)*EXP(-(A14+0.005)^2)-2*(A14+0.005)*(B14+D14/2)) -> -0.0012110601 | F14: =0.01*((A14+0.01)*EXP(-(A14+0.01)^2)-2*(A14+0.01)*(B14+E14)) -> -0.0012562435 | G14: =B14+(C14+2*D14+2*E14+F14)/6 -> 0.99169241
... A102: =A101+0.01 -> 1 | B102: =G101 -> 0.95548004 | C102: =0.01*(A102*EXP(-A102^2)-2*A102*B102) -> 0.0080732175 | D102: =0.01*((A102+0.005)*EXP(-(A102+0.005)^2)-2*(A102+0.005)*(B102+C102/2)) -> 0.0083076954 | E102: =0.01*((A102+0.005)*EXP(-(A102+0.005)^2)-2*(A102+0.005)*(B102+D102/2)) -> 0.0083053389 | F102: =0.01*((A102+0.01)*EXP(-(A102+0.01)^2)-2*(A102+0.01)*(B102+E102)) -> 0.0085436035 | G102: =B102+(C102+2*D102+2*E102+F102)/6 -> 0.96378719

Sheet Метод 5 (h = 0,001)
A1: x | B1: y | C1: k1 | D1: k2 | E1: k3 | F1: k4 | G1: y_new
A2: 0 | B2: 1 | C2: =0.001*(A2*EXP(-A2^2)-2*A2*B2) -> 0 | D2: =0.001*((A2+0.0005)*EXP(-(A2+0.0005)^2)-2*(A2+0.0005)*(B2+C2/2)) -> -4.9999987e-07 | E2: =0.001*((A2+0.0005)*EXP(-(A2+0.0005)^2)-2*(A2+0.0005)*(B2+D2/2)) -> -4.9999963e-07 | F2: =0.001*((A2+0.001)*EXP(-(A2+0.001)^2)-2*(A2+0.001)*(B2+E2)) -> -9.99998e-07 | G2: =B2+(C2+2*D2+2*E2+F2)/6 -> 0.9999995
A3: =A2+0.001 -> 0.001 | B3: =G2 -> 0.9999995 | C3: =0.001*(A3*EXP(-A3^2)-2*A3*B3) -> -9.99998e-07 | D3: =0.001*((A3+0.0005)*EXP(-(A3+0.0005)^2)-2*(A3+0.0005)*(B3+C3/2)) -> -1.4999936e-06 | E3: =0.001*((A3+0.0005)*EXP(-(A3+0.0005)^2)-2*(A3+0.0005)*(B3+D3/2)) -> -1.4999929e-06 | F3: =0.001*((A3+0.001)*EXP(-(A3+0.001)^2)-2*(A3+0.001)*(B3+E3)) -> -1.999984e-06 | G3: =B3+(C3+2*D3+2*E3+F3)/6 -> 0.999998
A4: =A3+0.001 -> 0.002 | B4: =G3 -> 0.999998 | C4: =0.001*(A4*EXP(-A4^2)-2*A4*B4) -> -1.999984e-06 | D4: =0.001*((A4+0.0005)*EXP(-(A4+0.0005)^2)-2*(A4+0.0005)*(B4+C4/2)) -> -2.4999694e-06 | E4: =0.001*((A4+0.0005)*EXP(-(A4+0.0005)^2)-2*(A4+0.0005)*(B4+D4/2)) -> -2.4999681e-06 | F4: =0.001*((A4+0.001)*EXP(-(A4+0.001)^2)-2*(A4+0.001)*(B4+E4)) -> -2.999946e-06 | G4: =B4+(C4+2*D4+2*E4+F4)/6 -> 0.9999955
A5: =A4+0.001 -> 0.003 | B5: =G4 -> 0.9999955 | C5: =0.001*(A5*EXP(-A5^2)-2*A5*B5) -> -2.999946e-06 | D5: =0.001*((A5+0.0005)*EXP(-(A5+0.0005)^2)-2*(A5+0.0005)*(B5+C5/2)) -> -3.4999151e-06 | E5: =0.001*((A5+0.0005)*EXP(-(A5+0.0005)^2)-2*(A5+0.0005)*(B5+D5/2)) -> -3.4999134e-06 | F5: =0.001*((A5+0.001)*EXP(-(A5+0.001)^2)-2*(A5+0.001)*(B5+E5)) -> -3.999872e-06 | G5: =B5+(C5+2*D5+2*E5+F5)/6 -> 0.999992
A6: =A5+0.001 -> 0.004 | B6: =G5 -> 0.999992 | C6: =0.001*(A6*EXP(-A6^2)-2*A6*B6) -> -3.999872e-06 | D6: =0.001*((A6+0.0005)*EXP(-(A6+0.0005)^2)-2*(A6+0.0005)*(B6+C6/2)) -> -4.4998189e-06 | E6: =0.001*((A6+0.0005)*EXP(-(A6+0.0005)^2)-2*(A6+0.0005)*(B6+D6/2)) -> -4.4998166e-06 | F6: =0.001*((A6+0.001)*EXP(-(A6+0.001)^2)-2*(A6+0.001)*(B6+E6)) -> -4.99975e-06 | G6: =B6+(C6+2*D6+2*E6+F6)/6 -> 0.9999875
A7: =A6+0.001 -> 0.005 | B7: =G6 -> 0.9999875 | C7: =0.001*(A7*EXP(-A7^2)-2*A7*B7) -> -4.99975e-06 | D7: =0.001*((A7+0.0005)*EXP(-(A7+0.0005)^2)-2*(A7+0.0005)*(B7+C7/2)) -> -5.4996686e-06 | E7: =0.001*((A7+0.0005)*EXP(-(A7+0.0005)^2)-2*(A7+0.0005)*(B7+D7/2)) -> -5.4996659e-06 | F7: =0.001*((A7+0.001)*EXP(-(A7+0.001)^2)-2*(A7+0.001)*(B7+E7)) -> -5.999568e-06 | G7: =B7+(C7+2*D7+2*E7+F7)/6 -> 0.999982
A8: =A7+0.001 -> 0.006 | B8: =G7 -> 0.999982 | C8: =0.001*(A8*EXP(-A8^2)-2*A8*B8) -> -5.999568e-06 | D8: =0.001*((A8+0.0005)*EXP(-(A8+0.0005)^2)-2*(A8+0.0005)*(B8+C8/2)) -> -6.4994524e-06 | E8: =0.001*((A8+0.0005)*EXP(-(A8+0.0005)^2)-2*(A8+0.0005)*(B8+D8/2)) -> -6.4994491e-06 | F8: =0.001*((A8+0.001)*EXP(-(A8+0.001)^2)-2*(A8+0.001)*(B8+E8)) -> -6.999314e-06 | G8: =B8+(C8+2*D8+2*E8+F8)/6 -> 0.9999755
A9: =A8+0.001 -> 0.007 | B9: =G8 -> 0.9999755 | C9: =0.001*(A9*EXP(-A9^2)-2*A9*B9) -> -6.999314e-06 | D9: =0.001*((A9+0.0005)*EXP(-(A9+0.0005)^2)-2*(A9+0.0005)*(B9+C9/2)) -> -7.4991581e-06 | E9: =0.001*((A9+0.0005)*EXP(-(A9+0.0005)^2)-2*(A9+0.0005)*(B9+D9/2)) -> -7.4991544e-06 | F9: =0.001*((A9+0.001)*EXP(-(A9+0.001)^2)-2*(A9+0.001)*(B9+E9)) -> -7.998976e-06 | G9: =B9+(C9+2*D9+2*E9+F9)/6 -> 0.999968
A10: =A9+0.001 -> 0.008 | B10: =G9 -> 0.999968 | C10: =0.001*(A10*EXP(-A10^2)-2*A10*B10) -> -7.998976e-06 | D10: =0.001*((A10+0.0005)*EXP(-(A10+0.0005)^2)-2*(A10+0.0005)*(B10+C10/2)) -> -8.4987739e-06 | E10: =0.001*((A10+0.0005)*EXP(-(A10+0.0005)^2)-2*(A10+0.0005)*(B10+D10/2)) -> -8.4987696e-06 | F10: =0.001*((A10+0.001)*EXP(-(A10+0.001)^2)-2*(A10+0.001)*(B10+E10)) -> -8.998542e-06 | G10: =B10+(C10+2*D10+2*E10+F10)/6 -> 0.9999595
A11: =A10+0.001 -> 0.009 | B11: =G10 -> 0.9999595 | C11: =0.001*(A11*EXP(-A11^2)-2*A11*B11) -> -8.998542e-06 | D11: =0.001*((A11+0.0005)*EXP(-(A11+0.0005)^2)-2*(A11+0.0005)*(B11+C11/2)) -> -9.4982877e-06 | E11: =0.001*((A11+0.0005)*EXP(-(A11+0.0005)^2)-2*(A11+0.0005)*(B11+D11/2)) -> -9.4982829e-06 | F11: =0.001*((A11+0.001)*EXP(-(A11+0.001)^2)-2*(A11+0.001)*(B11+E11)) -> -9.998e-06 | G11: =B11+(C11+2*D11+2*E11+F11)/6 -> 0.99995
A12: =A11+0.001 -> 0.01 | B12: =G11 -> 0.99995 | C12: =0.001*(A12*EXP(-A12^2)-2*A12*B12) -> -9.998e-06 | D12: =0.001*((A12+0.0005)*EXP(-(A12+0.0005)^2)-2*(A12+0.0005)*(B12+C12/2)) -> -1.0497687e-05 | E12: =0.001*((A12+0.0005)*EXP(-(A12+0.0005)^2)-2*(A12+0.0005)*(B12+D12/2)) -> -1.0497682e-05 | F12: =0.001*((A12+0.001)*EXP(-(A12+0.001)^2)-2*(A12+0.001)*(B12+E12)) -> -1.0997338e-05 | G12: =B12+(C12+2*D12+2*E12+F12)/6 -> 0.99993951
A13: =A12+0.001 -> 0.011 | B13: =G12 -> 0.99993951 | C13: =0.001*(A13*EXP(-A13^2)-2*A13*B13) -> -1.0997338e-05 | D13: =0.001*((A13+0.0005)*EXP(-(A13+0.0005)^2)-2*(A13+0.0005)*(B13+C13/2)) -> -1.1496961e-05 | E13: =0.001*((A13+0.0005)*EXP(-(A13+0.0005)^2)-2*(A13+0.0005)*(B13+D13/2)) -> -1.1496955e-05 | F13: =0.001*((A13+0.001)*EXP(-(A13+0.001)^2)-2*(A13+0.001)*(B13+E13)) -> -1.1996544e-05 | G13: =B13+(C13+2*D13+2*E13+F13)/6 -> 0.99992801
A14: =A13+0.001 -> 0.012 | B14: =G13 -> 0.99992801 | C14: =0.001*(A14*EXP(-A14^2)-2*A14*B14) -> -1.1996544e-05 | D14: =0.001*((A14+0.0005)*EXP(-(A14+0.0005)^2)-2*(A14+0.0005)*(B14+C14/2)) -> -1.2496097e-05 | E14: =0.001*((A14+0.0005)*EXP(-(A14+0.0005)^2)-2*(A14+0.0005)*(B14+D14/2)) -> -1.2496091e-05 | F14: =0.001*((A14+0.001)*EXP(-(A14+0.001)^2)-2*(A14+0.001)*(B14+E14)) -> -1.2995606e-05 | G14: =B14+(C14+2*D14+2*E14+F14)/6 -> 0.99991551
... A1002: =A1001+0.001 -> 1 | B1002: =G1001 -> 0.95548004 | C1002: =0.001*(A1002*EXP(-A1002^2)-2*A1002*B1002) -> 0.00080732175 | D1002: =0.001*((A1002+0.0005)*EXP(-(A1002+0.0005)^2)-2*(A1002+0.0005)*(B1002+C1002/2)) -> 0.00080963937 | E1002: =0.001*((A1002+0.0005)*EXP(-(A1002+0.0005)^2)-2*(A1002+0.0005)*(B1002+D1002/2)) -> 0.00080963705 | F1002: =0.001*((A1002+0.001)*EXP(-(A1002+0.001)^2)-2*(A1002+0.001)*(B1002+E1002)) -> 0.00081195835 | G1002: =B1002+(C1002+2*D1002+2*E1002+F1002)/6 -> 0.95628968
